$ python test_postgresdataapi.py
[2023-12-09 16:32:53,470] [test_postgresdataapi] [consolelogger] [setUp:14] [INFO]: "Connected to the database."
[2023-12-09 16:32:53,470] [test_postgresdataapi] [consolelogger] [test_connection:27] [INFO]: "Connection test passed."
[2023-12-09 16:32:53,470] [test_postgresdataapi] [consolelogger] [tearDown:22] [INFO]: "Closed the database connection."
.[2023-12-09 16:32:54,288] [test_postgresdataapi] [consolelogger] [setUp:14] [INFO]: "Connected to the database."
E[2023-12-09 16:32:54,304] [test_postgresdataapi] [consolelogger] [tearDown:22] [INFO]: "Closed the database connection."
[2023-12-09 16:32:54,968] [test_postgresdataapi] [consolelogger] [setUp:14] [INFO]: "Connected to the database."
E[2023-12-09 16:32:54,968] [test_postgresdataapi] [consolelogger] [tearDown:22] [INFO]: "Closed the database connection."
[2023-12-09 16:32:55,655] [test_postgresdataapi] [consolelogger] [setUp:14] [INFO]: "Connected to the database."
E[2023-12-09 16:32:55,671] [test_postgresdataapi] [consolelogger] [tearDown:22] [INFO]: "Closed the database connection."

======================================================================
ERROR: test_create_table (__main__.TestPostgresDataAPI.test_create_table)
----------------------------------------------------------------------
Traceback (most recent call last):
  File "D:\Users\A1086139\git_repo\adl-awsdeploy-cicd\tests\alight\foundation\postgres\test_postgresdataapi.py", line 32, in test_create_table
    self.data_api.execute_sql(sql_statement)
  File "D:\Users\A1086139\git_repo\adl-awsdeploy-cicd\src\alight\foundation\postgres\postgresdataapi.py", line 56, in execute_sql
    raise e
  File "D:\Users\A1086139\git_repo\adl-awsdeploy-cicd\src\alight\foundation\postgres\postgresdataapi.py", line 38, in execute_sql
    res = self._cursor.execute(Database=self._db_name, DbUser=self._db_user_name, Sql=sql_statement,
          ^^^^^^^^^^^^^^^^^^^^^^^^^^^^^^^^^^^^^^^^^^^^^^^^^^^^^^^^^^^^^^^^^^^^^^^^^^^^^^^^^^^^^^^^^^
TypeError: function takes at most 2 keyword arguments (4 given)

======================================================================
ERROR: test_select_from_table (__main__.TestPostgresDataAPI.test_select_from_table)
----------------------------------------------------------------------
Traceback (most recent call last):
  File "D:\Users\A1086139\git_repo\adl-awsdeploy-cicd\tests\alight\foundation\postgres\test_postgresdataapi.py", line 40, in test_select_from_table
    query_id, response = self.data_api.execute_sql(sql_statement)
                         ^^^^^^^^^^^^^^^^^^^^^^^^^^^^^^^^^^^^^^^^
  File "D:\Users\A1086139\git_repo\adl-awsdeploy-cicd\src\alight\foundation\postgres\postgresdataapi.py", line 56, in execute_sql
    raise e
  File "D:\Users\A1086139\git_repo\adl-awsdeploy-cicd\src\alight\foundation\postgres\postgresdataapi.py", line 38, in execute_sql
    res = self._cursor.execute(Database=self._db_name, DbUser=self._db_user_name, Sql=sql_statement,
          ^^^^^^^^^^^^^^^^^^^^^^^^^^^^^^^^^^^^^^^^^^^^^^^^^^^^^^^^^^^^^^^^^^^^^^^^^^^^^^^^^^^^^^^^^^
TypeError: function takes at most 2 keyword arguments (4 given)

======================================================================
ERROR: test_table_not_created_in_schema (__main__.TestPostgresDataAPI.test_table_not_created_in_schema)
----------------------------------------------------------------------
Traceback (most recent call last):
  File "D:\Users\A1086139\git_repo\adl-awsdeploy-cicd\tests\alight\foundation\postgres\test_postgresdataapi.py", line 49, in test_table_not_created_in_schema
    query_id, response = self.data_api.execute_sql(sql_statement)
                         ^^^^^^^^^^^^^^^^^^^^^^^^^^^^^^^^^^^^^^^^
  File "D:\Users\A1086139\git_repo\adl-awsdeploy-cicd\src\alight\foundation\postgres\postgresdataapi.py", line 56, in execute_sql
    raise e
  File "D:\Users\A1086139\git_repo\adl-awsdeploy-cicd\src\alight\foundation\postgres\postgresdataapi.py", line 38, in execute_sql
    res = self._cursor.execute(Database=self._db_name, DbUser=self._db_user_name, Sql=sql_statement,
          ^^^^^^^^^^^^^^^^^^^^^^^^^^^^^^^^^^^^^^^^^^^^^^^^^^^^^^^^^^^^^^^^^^^^^^^^^^^^^^^^^^^^^^^^^^
TypeError: function takes at most 2 keyword arguments (4 given)

----------------------------------------------------------------------
Ran 4 tests in 3.034s

FAILED (errors=3)
